Workbook
Name FundSize: 'Assumptions & Inputs'!$B$8
Name MgmtFee: 'Assumptions & Inputs'!$B$11
Name CarryRate: 'Assumptions & Inputs'!$B$12
Name HurdleRate: 'Assumptions & Inputs'!$B$13

Sheet Dashboard
B2: INFLECTION VENTURES FUND I Financial Model · Executive Summary
B3: Luxembourg ELTIF 2.0 · Longevity & Space Economy · Launch: Q2 2026 | G3: Status: | I3: Fundraising
B5: CAPITAL | D5: INVESTORS | F5: PORTFOLIO | H5: PERFORMANCE (Projected)
B6: Target Fund Size | C6: €3.0M – €5.0M | D6: Target Investors | E6: 300 – 500 | F6: Target Companies | G6: 15 – 20 | H6: Target MOIC | I6: 3x – 5x
B7: Capital Raised | C7: ='3-Year Operating Plan'!B6+'3-Year Operating Plan'!C6+'3-Year Operating Plan'!D6 | D7: Avg Commitment | E7: =FundSize/350 | F7: Current Companies | G7: ='Portfolio Construction'!B37 | H7: Target IRR | I7: 25% – 35%
B8: Capital Deployed | C8: =ABS('3-Year Operating Plan'!B7+'3-Year Operating Plan'!C7+'3-Year Operating Plan'!D7) | D8: Min Investment | E8: €10,000 | F8: Total Deployed | G8: ='Portfolio Construction'!B36 | H8: Management Fee | I8: 1.5%
B9: Available Capital | C9: =B8-B9 | D9: Fund Duration | E9: 10 years | F9: Portfolio MOIC | G9: ='Portfolio Construction'!B40 | H9: Carried Interest | I9: 25%
B10: Min Investment | C10: €10,000 | D10: Structure | E10: ELTIF 2.0 | F10: Avg Initial Ticket | G10: ='Assumptions & Inputs'!B22 | H10: Hurdle Rate | I10: 8.0%
B12: 3-YEAR FINANCIAL SUMMARY
B13: Metric | D13: Year 1 | F13: Year 2 | H13: Year 3
B14: AUM (Average, €) | D14: ='3-Year Operating Plan'!B9 | F14: ='3-Year Operating Plan'!C9 | H14: ='3-Year Operating Plan'!D9
B15: Management Fees (€) | D15: ='3-Year Operating Plan'!B12 | F15: ='3-Year Operating Plan'!C12 | H15: ='3-Year Operating Plan'!D12
B16: Operating Expenses (€) | D16: ='3-Year Operating Plan'!B27 | F16: ='3-Year Operating Plan'!C27 | H16: ='3-Year Operating Plan'!D27
B17: Net Cash Flow (€) | D17: ='3-Year Operating Plan'!B29 | F17: ='3-Year Operating Plan'!C29 | H17: ='3-Year Operating Plan'!D29
B18: Cumulative Cash Flow (€) | D18: ='3-Year Operating Plan'!B30 | F18: ='3-Year Operating Plan'!C30 | H18: ='3-Year Operating Plan'!D30
B20: VISUAL OVERVIEW
B38: Model Version: 1.0 · Last Updated: March 2026 | E38: → Fund Economics | F38: → Operating Plan | G38: → Portfolio | H38: → Scenarios | I38: → Inv. Calc
B40: Year 1 | C40: Year 2 | D40: Year 3 | E40: Year 4
A41: Deployed (€M) | B41: 0.5 | C41: 1.5 | D41: 2 | E41: 1
B43: Longevity | C43: Space
A44: Allocation | B44: 0.5 | C44: 0.5
B46: Year 1 | C46: Year 2 | D46: Year 3
A47: Revenue | B47: ='3-Year Operating Plan'!B12 | C47: ='3-Year Operating Plan'!C12 | D47: ='3-Year Operating Plan'!D12
A48: Expenses | B48: ='3-Year Operating Plan'!B27 | C48: ='3-Year Operating Plan'!C27 | D48: ='3-Year Operating Plan'!D27
A49: Net CF | B49: ='3-Year Operating Plan'!B29 | C49: ='3-Year Operating Plan'!C29 | D49: ='3-Year Operating Plan'!D29

Sheet Fund Economics
A1: FUND ECONOMICS
A3: A. FUND TERMS — INPUT SECTION
A4: Parameter | B4: Value | D4: Notes
A5: Fund Size (€) | B5: =FundSize | D5: Linked from Assumptions
A6: Management Fee (%) | B6: =MgmtFee | D6: Annual on committed capital
A7: Carried Interest (%) | B7: =CarryRate | D7: Above hurdle rate
A8: Hurdle Rate (%) | B8: =HurdleRate | D8: Annual preferred return
A9: Fund Duration (years) | B9: 10 | D9: Plus possible extensions
A10: Investment Period (yrs) | B10: 4 | D10: Active deployment
A12: CALCULATED FUND METRICS
A13: Annual Management Fee | B13: =B5*B6 | D13: → Auto-calculated from inputs above
A14: Total Mgmt Fees (10 years) | B14: =B13*B9 | D14: → Auto-calculated from inputs above
A15: Capital Available to Invest | B15: =B5*(1-0.02) | D15: → Auto-calculated from inputs above
A17: B. LP ECONOMICS CALCULATOR
A18: Adjust the yellow cells to model different investor scenarios
A20: Scenario Input | B20: Value | D20: What it means
A21: Investment Amount (€) | B21: 10000 | D21: Minimum: €10,000
A22: Portfolio MOIC | B22: 3 | D22: Expected gross fund multiple
A23: Years to Exit | B23: 7 | D23: Average holding period
A25: Portfolio Returns
A26: Gross Return (before fees) | B26: =B21*B22
A27: Gross Profit | B27: =B26-B21
A29: Hurdle & Carry Calculation
A30: Hurdle Amount (8% × years, compound) | B30: =B21*((1+B8)^B23)-B21
A31: Profit Above Hurdle | B31: =MAX(0,B27-B30)
A32: GP Carry (25% of excess) | B32: =B31*B7
A33: LP Share of Excess (75%) | B33: =B31*(1-B7)
A35: LP Total Return
A36: Return of Capital | B36: =B21
A37: Hurdle Return | B37: =B30
A38: 75% of Excess Profit | B38: =B33
A39: LP TOTAL DISTRIBUTION | B39: =B36+B37+B38
A40: LP Net Multiple | B40: =B39/B21
A41: LP Net IRR (approx.) | B41: =(B39/B21)^(1/B23)-1
A42: C. GP ECONOMICS
A43: Revenue Stream | B43: Amount | D43: Basis
A44: Annual Management Fee | B44: =B13 | D44: Fund Size × 1.5%
A45: Total Mgmt Fees (10 years) | B45: =B14 | D45: Annual Fee × 10
A47: Fund Size (for carry calc) | B47: =B5 | D47: From inputs
A48: Fund MOIC assumed | B48: =B22 | D48: From LP scenario above
...

Sheet 3-Year Operating Plan
A1: 3-YEAR OPERATING PLAN
A3: A. REVENUE
A4: Line Item | B4: Year 1 | C4: Year 2 | D4: Year 3 | E4: Notes
A5: Beginning AUM (€) | B5: 0 | C5: =D10 | D5: =E10 | E5: Carried from prior year
A6: (+) Capital Raised (€) | B6: 2000000 | C6: 2000000 | D6: 1000000 | E6: User input – adjust as needed
A7: (−) Capital Deployed (€) | B7: -500000 | C7: -1500000 | D7: -2000000 | E7: Negative = outflow to portfolio
A8: Ending AUM (€) | B8: =D5+D6+D7 | C8: =E5+E6+E7 | D8: =F5+F6+F7 | E8: Beginning + Raised + Deployed
A9: Average AUM (€) | B9: =(D5+D8)/2 | C9: =(E5+E8)/2 | D9: =(F5+F8)/2 | E9: (Beginning + Ending) / 2
A11: MANAGEMENT FEE REVENUE
A12: Management Fee Revenue (1.5%) | B12: =B9*'Fund Economics'!B6 | C12: =C9*'Fund Economics'!B6 | D12: =D9*'Fund Economics'!B6 | E12: Avg AUM × 1.5%
A13: Total Revenue | B13: =B12 | C13: =C12 | D13: =D12 | E13: =Management Fee
A15: B. OPERATING EXPENSES
A16: Category | B16: Year 1 | C16: Year 2 | D16: Year 3 | E16: Notes
A17: Legal & Compliance | B17: ='Assumptions & Inputs'!B40 | C17: ='Assumptions & Inputs'!C40 | D17: ='Assumptions & Inputs'!D40 | E17: Fund counsel, regulatory
A18: Fund Administration | B18: ='Assumptions & Inputs'!B41 | C18: ='Assumptions & Inputs'!C41 | D18: ='Assumptions & Inputs'!D41 | E18: NAV, reporting, accounting
A19: Auditor | B19: ='Assumptions & Inputs'!B42 | C19: ='Assumptions & Inputs'!C42 | D19: ='Assumptions & Inputs'!D42 | E19: Annual audit
A20: ELTIF Depositary | B20: ='Assumptions & Inputs'!B43 | C20: ='Assumptions & Inputs'!C43 | D20: ='Assumptions & Inputs'!D43 | E20: Custody services
A21: Platform & Technology | B21: ='Assumptions & Inputs'!B44 | C21: ='Assumptions & Inputs'!C44 | D21: ='Assumptions & Inputs'!D44 | E21: Investor portal, hosting
A22: KYC/AML | B22: ='Assumptions & Inputs'!B45 | C22: ='Assumptions & Inputs'!C45 | D22: ='Assumptions & Inputs'!D45 | E22: Onboarding (higher Y1)
A23: Marketing & Events | B23: ='Assumptions & Inputs'!B46 | C23: ='Assumptions & Inputs'!C46 | D23: ='Assumptions & Inputs'!D46 | E23: Investor acquisition
A24: Insurance (D&O, E&O) | B24: ='Assumptions & Inputs'!B47 | C24: ='Assumptions & Inputs'!C47 | D24: ='Assumptions & Inputs'!D47
A25: Bank Fees | B25: ='Assumptions & Inputs'!B48 | C25: ='Assumptions & Inputs'!C48 | D25: ='Assumptions & Inputs'!D48 | E25: Account maintenance
A26: Other / Contingency | B26: ='Assumptions & Inputs'!B49 | C26: ='Assumptions & Inputs'!C49 | D26: ='Assumptions & Inputs'!D49 | E26: Buffer
A27: TOTAL EXPENSES | B27: =SUM(B17:B26) | C27: =SUM(C17:C26) | D27: =SUM(D17:D26)
A29: C. CASH FLOW SUMMARY
A30: Line Item | B30: Year 1 | C30: Year 2 | D30: Year 3
A31: Revenue (Mgmt Fees) | B31: =B13 | C31: =C13 | D31: =D13
A32: Operating Expenses | B32: =B27 | C32: =C27 | D32: =D27
A33: Net Operating Cash Flow | B33: =B31-B32 | C33: =C31-C32 | D33: =D31-D32
A34: Cumulative Cash Flow | B34: =B33 | C34: =B34+C33 | D34: =C34+D33
A36: FUNDING GAP COVERAGE
A37: Grant Funding (target) | B37: 30000
A38: GP Capital Contribution | B38: 20000
A39: Total Gap Coverage | B39: =B37+B38
A40: Adjusted Cumulative CF (Y3) | B40: =D34+B39
A42: D. BREAK-EVEN ANALYSIS
A43: Average Annual Operating Expenses | B43: =AVERAGE(B27,C27,D27)
A44: Break-Even AUM (÷ 1.5% mgmt fee) | B44: =B43/MgmtFee
A45: → Fund reaches operational break-even at this AUM level
A48: CHART DATA (for charts below)
...

Sheet Portfolio Construction
A1: PORTFOLIO CONSTRUCTION
A3: A. PORTFOLIO PARAMETERS
A4: Parameter | B4: Value | C4: Notes
A5: Total Fund Size (€) | B5: =FundSize | C5: Linked from Assumptions
A6: Target Companies | B6: ='Assumptions & Inputs'!B19 | C6: Range 15–20
A7: Follow-On Reserve (%) | B7: ='Assumptions & Inputs'!B23 | C7: 30% of fund
A8: Capital for Initial Investments (€) | B8: =B5*(1-B7) | C8: Fund × (1 − Follow-On %)
A9: Avg Initial Ticket (€) | B9: =B8/B6 | C9: Initial Capital ÷ # Companies
A10: Avg Follow-On per Company (€) | B10: =B5*B7/B6 | C10: Follow-On Capital ÷ # Companies
A12: B. PORTFOLIO COMPANIES
A13: # | B13: Company Name | C13: Sector | D13: Stage | E13: Inv. Date | F13: Initial Inv. (€) | G13: Follow-On (€) | H13: Total Inv. (€) | I13: Curr. Val. (€) | J13: MOIC | K13: Status
A14: 1 | F14: 0 | G14: 0 | H14: =F14+G14 | I14: 0 | J14: =IF(H14>0,I14/H14,0)
A15: 2 | F15: 0 | G15: 0 | H15: =F15+G15 | I15: 0 | J15: =IF(H15>0,I15/H15,0)
A16: 3 | F16: 0 | G16: 0 | H16: =F16+G16 | I16: 0 | J16: =IF(H16>0,I16/H16,0)
A17: 4 | F17: 0 | G17: 0 | H17: =F17+G17 | I17: 0 | J17: =IF(H17>0,I17/H17,0)
A18: 5 | F18: 0 | G18: 0 | H18: =F18+G18 | I18: 0 | J18: =IF(H18>0,I18/H18,0)
A19: 6 | F19: 0 | G19: 0 | H19: =F19+G19 | I19: 0 | J19: =IF(H19>0,I19/H19,0)
A20: 7 | F20: 0 | G20: 0 | H20: =F20+G20 | I20: 0 | J20: =IF(H20>0,I20/H20,0)
A21: 8 | F21: 0 | G21: 0 | H21: =F21+G21 | I21: 0 | J21: =IF(H21>0,I21/H21,0)
A22: 9 | F22: 0 | G22: 0 | H22: =F22+G22 | I22: 0 | J22: =IF(H22>0,I22/H22,0)
A23: 10 | F23: 0 | G23: 0 | H23: =F23+G23 | I23: 0 | J23: =IF(H23>0,I23/H23,0)
A24: 11 | F24: 0 | G24: 0 | H24: =F24+G24 | I24: 0 | J24: =IF(H24>0,I24/H24,0)
A25: 12 | F25: 0 | G25: 0 | H25: =F25+G25 | I25: 0 | J25: =IF(H25>0,I25/H25,0)
... A33: 20 | F33: 0 | G33: 0 | H33: =F33+G33 | I33: 0 | J33: =IF(H33>0,I33/H33,0)
A36: C. PORTFOLIO SUMMARY
A37: Total Companies | B37: =COUNTA(B14:B33)
A38: Total Deployed (€) | B38: =SUM(H14:H33)
A39: Longevity Companies | B39: =COUNTA(B14:B33)
A40: Space Companies | B40: =COUNTIF(C14:C33,"Space")
A41: Current Portfolio Value (€) | B41: =SUM(I14:I33)
A42: PORTFOLIO MOIC | B42: =IF(SUM(H14:H33)>0,SUM(I14:I33)/SUM(H14:H33),0)
A46: D. DEPLOYMENT SCHEDULE
A47: Year | B47: Target Capital (€) | C47: # Companies | D47: Avg Ticket (€) | E47: Notes
A48: Year 1 | B48: 500000 | C48: 3–4 | D48: =B48/3.5 | E48: First investments
A49: Year 2 | B49: 1500000 | C49: 5–6 | D49: =B49/5.5 | E49: Acceleration
A50: Year 3 | B50: 2000000 | C50: 5–6 | D50: =B50/5.5 | E50: Main deployment
A51: Year 4 | B51: 1000000 | C51: 3–4 | D51: =B51/3.5 | E51: Follow-ons & final investments
A52: TOTAL | B52: =SUM(B48:B51)
A54: Longevity | B54: =COUNTIF(C14:C33,"Longevity")
A55: Space | B55: =COUNTIF(C14:C33,"Space")

Sheet Scenario Analysis
A1: SCENARIO ANALYSIS
A3: A. SCENARIO INPUTS
A4: Parameter | B4: Best Case | C4: Base Case | D4: Worst Case | E4: Notes
A5: Fund Size (€) | B5: 5000000 | C5: 3000000 | D5: 1000000 | E5: Total AUM raised
A6: Portfolio MOIC | B6: 5 | C6: 3 | D6: 1 | E6: Gross fund multiple
A7: Years to Exit (avg) | B7: 6 | C7: 7 | D7: 9 | E7: Average holding period
A8: Avg Annual Op Expenses (€) | B8: 60000 | C8: 70000 | D8: 80000 | E8: Total annual expenses
A9: Management Fee (%) | B9: 0.015 | C9: 0.015 | D9: 0.015 | E9: Fixed at 1.5%
A10: Carried Interest (%) | B10: 0.25 | C10: 0.25 | D10: 0.25 | E10: Fixed at 25%
A12: B. SCENARIO OUTCOMES
A13: Metric | B13: Best Case | C13: Base Case | D13: Worst Case | E13: Formula basis
A14: Fund Returns (Gross) | B14: =B5*B6 | C14: =C5*C6 | D14: =D5*D6 | E14: Fund Size × MOIC
A15: Gross Profit | B15: =B14-B5 | C15: =C14-C5 | D15: =D14-D5 | E15: Returns − Fund Size
A16: Hurdle to LPs (8% comp.) | B16: =B5*((1+B10)^B7)-B5 | C16: =C5*((1+C10)^C7)-C5 | D16: =D5*((1+D10)^D7)-D5 | E16: Fund × (1.08^yrs) − Fund
A17: Profit Above Hurdle | B17: =MAX(0,B15-B16) | C17: =MAX(0,C15-C16) | D17: =MAX(0,D15-D16) | E17: MAX(0, Profit − Hurdle)
A18: GP Carry (25%) | B18: =B17*B11 | C18: =C17*C11 | D18: =D17*D11 | E18: Excess × 25%
A19: LP Net Returns | B19: =B5+B16+(B17*0.75) | C19: =C5+C16+(C17*0.75) | D19: =D5+D16+(D17*0.75) | E19: Capital+Hurdle+75%Excess
A20: LP Net Multiple | B20: =B19/B5 | C20: =C19/C5 | D20: =D19/D5 | E20: LP Returns ÷ Fund Size
A21: LP Net IRR (approx.) | B21: =(B19/B5)^(1/B7)-1 | C21: =(C19/C5)^(1/C7)-1 | D21: =(D19/D5)^(1/D7)-1 | E21: (Multiple)^(1/Years)−1
A22: Mgmt Fees (10 years) | B22: =B5*B10*10 | C22: =C5*C10*10 | D22: =D5*D10*10 | E22: Fund × 1.5% × 10
A23: GP Total Compensation | B23: =B22+B18 | C23: =C22+C18 | D23: =D22+D18 | E23: Mgmt Fees + Carry
A25: C. SCENARIO COMPARISON SUMMARY
A26: Metric | B26: Best Case | C26: Base Case | D26: Worst Case
A27: Fund Size (€) | B27: =B5 | C27: =C5 | D27: =D5
A28: Gross Returns (€) | B28: =B14 | C28: =C14 | D28: =D14
A29: LP Net Multiple | B29: =B20 | C29: =C20 | D29: =D20
A30: LP Net IRR | B30: =B21 | C30: =C21 | D30: =D21
A31: GP Total Comp (€) | B31: =B23 | C31: =C23 | D31: =D23
A32: Mgmt Fees 10yr (€) | B32: =B22 | C32: =C22 | D32: =D22
A33: GP Carry (€) | B33: =B18 | C33: =C18 | D33: =D18
A35: D. SENSITIVITY — LP NET IRR BY FUND SIZE & MOIC
A36: Rows = Portfolio MOIC | Columns = Fund Size (for reference, IRR is size-independent)
A37: MOIC \ Years | B37: 5 yrs | C37: 6 yrs | D37: 7 yrs | E37: 8 yrs | F37: 9 yrs | G37: 10 yrs
A38: 1.0x | B38: 0 | C38: 0 | D38: 0 | E38: 0 | F38: 0 | G38: 0
A39: 1.5x | B39: 0.084471771 | C39: 0.069913194 | D39: 0.059634023 | E39: 0.051989506 | F39: 0.046081919 | G39: 0.041379744
A40: 2.0x | B40: 0.14869835 | C40: 0.12246205 | D40: 0.10408951 | E40: 0.090507733 | F40: 0.080059739 | G40: 0.071773463
A41: 2.5x | B41: 0.20112443 | C41: 0.16499305 | D41: 0.13985228 | E41: 0.12135339 | F41: 0.10717318 | G41: 0.095958226
A42: 3.0x | B42: 0.24573094 | C42: 0.20093696 | D42: 0.16993081 | E42: 0.14720269 | F42: 0.12983096 | G42: 0.11612317
A43: 3.5x | B43: 0.28473516 | C43: 0.23219093 | D43: 0.19598025 | E43: 0.1695223 | F43: 0.14934922 | G43: 0.13346158
A44: 4.0x | B44: 0.31950791 | C44: 0.25992105 | D44: 0.21901365 | E44: 0.18920712 | F44: 0.16652904 | G44: 0.14869835
...

Sheet Investor Calculator
A1: INVESTOR RETURNS CALCULATOR
A2: Interactive tool — change the yellow cells to model your potential returns
A4: A. YOUR INVESTMENT (Edit yellow cells)
A5: Input | B5: Your Value | D5: Guidance
A6: Investment Amount (€) | B6: 10000 | D6: Minimum €10,000
A7: Expected Portfolio MOIC | B7: 3 | D7: Dropdown: 1x–10x
A8: Holding Period (years) | B8: 7 | D8: Range: 5–10 years
A10: B. YOUR PROJECTED RETURNS
A11: All calculations use the 8% hurdle rate and 25% carried interest structure of the fund
A13: Initial Investment | B13: =B6
A14: Gross Return (before fees) | B14: =B6*B7
A15: Gross Profit | B15: =B14-B6
A17: Preferred Return (8% hurdle) | B17: =B6*((1.08^B8)-1)
A18: You Receive First (Capital+Hurdle) | B18: =B6+B17
A20: Remaining Profit Above Hurdle | B20: =MAX(0,B15-B17)
A21: Your 75% Share | B21: =B20*0.75
A22: GP Carry 25% | B22: =B20*0.25
A24: YOUR TOTAL DISTRIBUTION | B24: =B18+B21
A25: YOUR NET MULTIPLE | B25: =B23/B6
A26: YOUR NET IRR (approx.) | B26: =(B23/B6)^(1/B8)-1
A28: C. SCENARIO COMPARISON (based on your investment amount)
A29: Scenario | B29: Portfolio MOIC | C29: Your Investment | D29: Your Distribution | E29: Your Multiple | F29: Your IRR
A30: Conservative | B30: 2 | C30: =$B$6 | D30: =$B$6+$B$6*((1.08^$B$8)-1)+(MAX(0,$B$6*B30-$B$6-$B$6*((1.08^$B$8)-1))*0.75) | E30: =E30/$B$6 | F30: =(E30/$B$6)^(1/$B$8)-1
A31: Base Case | B31: 3 | C31: =$B$6 | D31: =$B$6+$B$6*((1.08^$B$8)-1)+(MAX(0,$B$6*B31-$B$6-$B$6*((1.08^$B$8)-1))*0.75) | E31: =E31/$B$6 | F31: =(E31/$B$6)^(1/$B$8)-1
A32: Optimistic | B32: 5 | C32: =$B$6 | D32: =$B$6+$B$6*((1.08^$B$8)-1)+(MAX(0,$B$6*B32-$B$6-$B$6*((1.08^$B$8)-1))*0.75) | E32: =E32/$B$6 | F32: =(E32/$B$6)^(1/$B$8)-1
A34: D. FEE IMPACT ANALYSIS
A35: Item | B35: Amount
A36: Gross Returns (before fees) | B36: =B6*B7
A37: Gross Multiple | B37: =B7
A38: Mgmt Fees Impact (1.5% × 10yr) | B38: =B6*0.015*10
A39: Carry Paid to GP | B39: =B22
A40: Net to You | B40: =B23
A41: Net Multiple | B41: =B24
A42: Blended Fee Rate | B42: =IF(B36>0,(B38+B39)/B36,0)
A44: IMPORTANT RISK DISCLAIMER
A45: This calculator provides illustrative projections only. Actual returns may vary significantly. Venture capital investments are high-risk and illiquid. You could lose your entire investment. Past performance (if any) does not guarantee future results. MOIC and IRR targets are aspirational, not promises. Inflection Ventures Fund I is not yet regulated or approved by any authority.

Sheet Assumptions & Inputs
A1: INFLECTION VENTURES – ASSUMPTIONS & INPUTS
A2: All yellow cells are user-adjustable. Other sheets reference values here.
A4: A. FUND PARAMETERS
A5: Parameter | B5: Value | E5: Notes
A6: Fund Name | B6: Inflection Ventures Fund I | E6: Legal entity name
A7: Legal Structure | B7: Luxembourg ELTIF 2.0 | E7: EU regulatory framework
A8: Fund Size (Target €) | B8: 3000000 | E8: User adjustable – base case €3M
A9: Minimum Investment (€) | B9: 10000 | E9: ELTIF 2.0 minimum
A10: Target Investors | B10: 300-500 | E10: Range
A11: Management Fee (%) | B11: 0.015 | E11: Annual, on committed capital
A12: Carried Interest (%) | B12: 0.25 | E12: Above hurdle rate
A13: Hurdle Rate (%) | B13: 0.08 | E13: Annual preferred return
A14: Fund Duration (years) | B14: 10 | E14: Plus possible extensions
A15: Investment Period (years) | B15: 4 | E15: Active deployment window
A17: B. PORTFOLIO PARAMETERS
A18: Parameter | B18: Value | E18: Notes
A19: Target Companies (total) | B19: 18 | E19: Range 15–20
A20: Longevity Companies | B20: 9 | E20: ~50% of portfolio
A21: Space Companies | B21: 9 | E21: ~50% of portfolio
A22: Average Initial Ticket (€) | B22: 200000 | E22: €150K–€250K range
A23: Follow-On Reserve (%) | B23: 0.3 | E23: 30% of fund reserved
A24: Geographic – EU (%) | B24: 0.7 | E24: ELTIF 2.0 compliance
A25: Geographic – US/Other (%) | B25: 0.3
A26: Stage Focus | B26: Pre-seed, Seed, Series A | E26: Early-stage only
A28: C. RETURN ASSUMPTIONS
A29: Scenario | B29: Portfolio MOIC | C29: Timeline (yrs) | E29: Notes
A30: Conservative | B30: 2 | C30: 8–9 | E30: Base case survival rate
A31: Base Case | B31: 3 | C31: 7 | E31: Target returns
A32: Optimistic | B32: 5 | C32: 6 | E32: Strong portfolio
A33: Failures (40-50%) | B33: 0–0.5x | E33: Total loss or near-loss
A34: Modest Returns (30-40%) | B34: 0.5–2x | E34: Return capital or small gain
A35: Good Returns (10-20%) | B35: 3–10x | E35: Solid returns
A36: Exceptional (5-10%) | B36: 10x+ | E36: Home runs
A38: D. OPERATING EXPENSE ASSUMPTIONS
A39: Category | B39: Year 1 | C39: Year 2 | D39: Year 3 | E39: Growth Rate
A40: Legal & Compliance | B40: 25000 | C40: 25000 | D40: 25000 | E40: Flat
A41: Fund Administration | B41: 18000 | C41: 22000 | D41: 25000 | E41: +15–20%
A42: Auditor | B42: 10000 | C42: 12000 | D42: 15000 | E42: +20%
A43: ELTIF Depositary | B43: 8000 | C43: 10000 | D43: 12000 | E43: +20%
A44: Platform & Technology | B44: 12000 | C44: 12000 | D44: 15000 | E44: +0–25%
...
